<?xml version="1.0" encoding="UTF-8"?>
<!-- Generated by org.testng.reporters.JUnitReportReporter -->
<testsuite hostname="Legend" failures="1" tests="6" name="com.app.tests.APIBasicTestsReview" time="5.014" errors="0" timestamp="16 Jan 2019 23:44:52 GMT" skipped="0">
  <testcase classname="com.app.tests.APIBasicTestsReview" name="getWithHeaders" time="0.218"/>
  <testcase classname="com.app.tests.APIBasicTestsReview" name="printRequestBody" time="0.330"/>
  <testcase classname="com.app.tests.APIBasicTestsReview" name="negativeGet" time="0.262">
    <failure message="The following asserts failed:
	this is wrong expected [202] but found [404],
	this is wrong expected [true] but found [false]" type="java.lang.AssertionError">
      <![CDATA[java.lang.AssertionError: The following asserts failed:
this is wrong expected [202] but found [404],
this is wrong expected [true] but found [false]
at org.testng.asserts.SoftAssert.assertAll(SoftAssert.java:43)
at com.app.tests.APIBasicTestsReview.negativeGet(APIBasicTestsReview.java:56)
at java.base/jdk.internal.reflect.NativeMethodAccessorImpl.invoke0(Native Method)
at java.base/jdk.internal.reflect.NativeMethodAccessorImpl.invoke(Unknown Source)
at java.base/jdk.internal.reflect.DelegatingMethodAccessorImpl.invoke(Unknown Source)
at java.base/java.lang.reflect.Method.invoke(Unknown Source)
at org.testng.internal.MethodInvocationHelper.invokeMethod(MethodInvocationHelper.java:124)
at org.testng.internal.Invoker.invokeMethod(Invoker.java:583)
at org.testng.internal.Invoker.invokeTestMethod(Invoker.java:719)
at org.testng.internal.Invoker.invokeTestMethods(Invoker.java:989)
at org.testng.internal.TestMethodWorker.invokeTestMethods(TestMethodWorker.java:125)
at org.testng.internal.TestMethodWorker.run(TestMethodWorker.java:109)
at org.testng.TestRunner.privateRun(TestRunner.java:648)
at org.testng.TestRunner.run(TestRunner.java:505)
at org.testng.SuiteRunner.runTest(SuiteRunner.java:455)
at org.testng.SuiteRunner.runSequentially(SuiteRunner.java:450)
at org.testng.SuiteRunner.privateRun(SuiteRunner.java:415)
at org.testng.SuiteRunner.run(SuiteRunner.java:364)
at org.testng.SuiteRunnerWorker.runSuite(SuiteRunnerWorker.java:52)
at org.testng.SuiteRunnerWorker.run(SuiteRunnerWorker.java:84)
at org.testng.TestNG.runSuitesSequentially(TestNG.java:1208)
at org.testng.TestNG.runSuitesLocally(TestNG.java:1137)
at org.testng.TestNG.runSuites(TestNG.java:1049)
at org.testng.TestNG.run(TestNG.java:1017)
at org.testng.remote.AbstractRemoteTestNG.run(AbstractRemoteTestNG.java:114)
at org.testng.remote.RemoteTestNG.initAndRun(RemoteTestNG.java:251)
at org.testng.remote.RemoteTestNG.main(RemoteTestNG.java:77)
]]>
    </failure>
  </testcase> <!-- negativeGet -->
  <testcase classname="com.app.tests.APIBasicTestsReview" name="verifyCOntentTYpeWithAssertThat" time="0.237"/>
  <testcase classname="com.app.tests.APIBasicTestsReview" name="verifyFirstName" time="0.992"/>
  <testcase classname="com.app.tests.APIBasicTestsReview" name="basicTest" time="2.975"/>
</testsuite> <!-- com.app.tests.APIBasicTestsReview -->
